Workbook

Sheet Sheet1
A1: pos | B1: upos | C1: lemma | D1: senseID | E1: definition | F1: literals | G1: domain | H1: source | I1: Type | J1: Dužina | L1: Akcija
A2: N | B2: NOUN | C2: atomski radjus | D2: LLM-0009 | E2: udaljenost od jezgra atoma do njegove spoljne elektronske ljuske. | H2: ChatGPT 4.5 | I2: NID | J2: =len(E2) -> 65 | K2: =D2&C2 -> LLM-0009atomski radjus | L2: =ifna(VLOOKUP(K2,'Лист1'!D:E,2,false))
A3: N | B3: NOUN | C3: beli pirinač | D3: LLM-0015 | E3: pirinač sa koga su uklonjene spoljašnje ljuske i klica, čime gubi deo hranljivih sastojaka, ali ima duži rok trajanja. | H3: ChatGPT 4.5 | I3: NID | J3: =len(E3) -> 118 | K3: =D3&C3 -> LLM-0015beli pirinač | L3: =ifna(VLOOKUP(K3,'Лист1'!D:E,2,false))
A4: V | B4: VERB | C4: biti u nečijim rukama | D4: LLM-0020 | E4: biti pod nečijom kontrolom. | H4: ChatGPT 4.5 | I4: VID | J4: =len(E4) -> 27 | K4: =D4&C4 -> LLM-0020biti u nečijim rukama | L4: =ifna(VLOOKUP(K4,'Лист1'!D:E,2,false))
A5: V | B5: VERB | C5: biti u rukama | D5: LLM-0020 | E5: biti pod nečijom kontrolom. | H5: ChatGPT 4.5 | I5: VID | J5: =len(E5) -> 27 | K5: =D5&C5 -> LLM-0020biti u rukama | L5: =ifna(VLOOKUP(K5,'Лист1'!D:E,2,false))
A6: N | B6: NOUN | C6: devizni kurs | D6: LLM-0029 | E6: vrednost jedne valute izražena u drugoj valuti | H6: ChatGPT 4.5 | I6: NID | J6: =len(E6) -> 46 | K6: =D6&C6 -> LLM-0029devizni kurs | L6: =ifna(VLOOKUP(K6,'Лист1'!D:E,2,false))
A7: N | B7: NOUN | C7: društvena mreža | D7: LLM-0039 | E7: digitalna platforma za povezivanje, komunikaciju i interakciju između korisnika. | H7: ChatGPT 4.5 | I7: NID | J7: =len(E7) -> 80 | K7: =D7&C7 -> LLM-0039društvena mreža | L7: =ifna(VLOOKUP(K7,'Лист1'!D:E,2,false))
A8: N | B8: NOUN | C8: državne granice | D8: LLM-0042 | E8: teritorijalne granice kojima država definiše svoju jurisdikciju. | H8: ChatGPT 4.5 | I8: NID | J8: =len(E8) -> 64 | K8: =D8&C8 -> LLM-0042državne granice | L8: =ifna(VLOOKUP(K8,'Лист1'!D:E,2,false))
A9: N | B9: NOUN | C9: geografski položaj | D9: LLM-0057 | E9: lokacija nekog mesta određena geografskim koordinatama. | H9: ChatGPT 4.5 | I9: NID | J9: =len(E9) -> 55 | K9: =D9&C9 -> LLM-0057geografski položaj | L9: =ifna(VLOOKUP(K9,'Лист1'!D:E,2,false))
A10: N | B10: NOUN | C10: gravitacioni bunar | D10: LLM-0058 | E10: metaforični opis gravitacionog polja oko masivnog tela iz kojeg je potrebna energija za izlazak. | H10: ChatGPT 4.5 | I10: NID | J10: =len(E10) -> 96 | K10: =D10&C10 -> LLM-0058gravitacioni bunar | L10: =ifna(VLOOKUP(K10,'Лист1'!D:E,2,false))
A11: V | B11: VERB | C11: ima uticaj | D11: LLM-0068 | E11: odrednica: imati uticaj; delovati, uticati na nekoga ili nešto | H11: ChatGPT 4.5 | I11: LVC.full | J11: =len(E11) -> 62 | K11: =D11&C11 -> LLM-0068ima uticaj | L11: =ifna(VLOOKUP(K11,'Лист1'!D:E,2,false))
A12: N | B12: NOUN | C12: industrijska revolucija | D12: LLM-0072 | E12: istorijski period intenzivne industrijalizacije, posebno od kraja 18. do sredine 19. veka. | H12: ChatGPT 4.5 | I12: NID | J12: =len(E12) -> 90 | K12: =D12&C12 -> LLM-0072industrijska revolucija | L12: =ifna(VLOOKUP(K12,'Лист1'!D:E,2,false))
A13: N | B13: NOUN | C13: informaciona tehnologija | D13: LLM-0073 | E13: oblast koja se bavi primenom računara i softvera za upravljanje informacijama. | H13: ChatGPT 4.5 | I13: NID | J13: =len(E13) -> 78 | K13: =D13&C13 -> LLM-0073informaciona tehnologija | L13: =ifna(VLOOKUP(K13,'Лист1'!D:E,2,false))
... A227: A | B227: ADJ | C227: Zamljin | D227: CVDf-397/0 | E227: prisvojni pridev od Zamlja | H227: Cvetana | I227: S | J227: =len(E227) -> 26 | K227: =D227&C227 -> CVDf-397/0Zamljin | L227: =ifna(VLOOKUP(K227,'Лист1'!D:E,2,false))
A228: RN | B228: ADJ | C228: 1. | D228: CVDf-398/1 | E228: ="redni broj od kardinalnog broja " & substitute(C228,".","") -> redni broj od kardinalnog broja 1 | H228: Cvetana | I228: S | J228: =len(E228) -> 33 | K228: =D228&C228 -> CVDf-398/11. | L228: =ifna(VLOOKUP(K228,'Лист1'!D:E,2,false))
A229: RN | B229: ADJ | C229: 10. | D229: ="CVDf-"& mid(D228,6,3)+1 &"/1" -> CVDf-399/1 | E229: ="redni broj od kardinalnog broja " & substitute(C229,".","") -> redni broj od kardinalnog broja 10 | H229: Cvetana | I229: S | J229: =len(E229) -> 34 | K229: =D229&C229 -> CVDf-399/110. | L229: =ifna(VLOOKUP(K229,'Лист1'!D:E,2,false))
A230: RN | B230: ADJ | C230: 1014. | D230: ="CVDf-"& mid(D229,6,3)+1 &"/1" -> CVDf-400/1 | E230: ="redni broj od kardinalnog broja " & substitute(C230,".","") -> redni broj od kardinalnog broja 1014 | H230: Cvetana | I230: S | J230: =len(E230) -> 36 | K230: =D230&C230 -> CVDf-400/11014. | L230: =ifna(VLOOKUP(K230,'Лист1'!D:E,2,false))
A231: RN | B231: ADJ | C231: 1030. | D231: ="CVDf-"& mid(D230,6,3)+1 &"/1" -> CVDf-401/1 | E231: ="redni broj od kardinalnog broja " & substitute(C231,".","") -> redni broj od kardinalnog broja 1030 | H231: Cvetana | I231: S | J231: =len(E231) -> 36 | K231: =D231&C231 -> CVDf-401/11030. | L231: =ifna(VLOOKUP(K231,'Лист1'!D:E,2,false))
A232: RN | B232: ADJ | C232: 1066. | D232: ="CVDf-"& mid(D231,6,3)+1 &"/1" -> CVDf-402/1 | E232: ="redni broj od kardinalnog broja " & substitute(C232,".","") -> redni broj od kardinalnog broja 1066 | H232: Cvetana | I232: S | J232: =len(E232) -> 36 | K232: =D232&C232 -> CVDf-402/11066. | L232: =ifna(VLOOKUP(K232,'Лист1'!D:E,2,false))
A233: RN | B233: ADJ | C233: 1088. | D233: ="CVDf-"& mid(D232,6,3)+1 &"/1" -> CVDf-403/1 | E233: ="redni broj od kardinalnog broja " & substitute(C233,".","") -> redni broj od kardinalnog broja 1088 | H233: Cvetana | I233: S | J233: =len(E233) -> 36 | K233: =D233&C233 -> CVDf-403/11088. | L233: =ifna(VLOOKUP(K233,'Лист1'!D:E,2,false))
A234: RN | B234: ADJ | C234: 1093 | D234: ="CVDf-"& mid(D233,6,3)+1 &"/1" -> CVDf-404/1 | E234: ="redni broj od kardinalnog broja " & substitute(C234,".","") -> redni broj od kardinalnog broja 1093 | H234: Cvetana | I234: S | J234: =len(E234) -> 36 | K234: =D234&C234 -> CVDf-404/11093 | L234: =ifna(VLOOKUP(K234,'Лист1'!D:E,2,false))
A235: RN | B235: ADJ | C235: 1095. | D235: ="CVDf-"& mid(D234,6,3)+1 &"/1" -> CVDf-405/1 | E235: ="redni broj od kardinalnog broja " & substitute(C235,".","") -> redni broj od kardinalnog broja 1095 | H235: Cvetana | I235: S | J235: =len(E235) -> 36 | K235: =D235&C235 -> CVDf-405/11095. | L235: =ifna(VLOOKUP(K235,'Лист1'!D:E,2,false))
A236: RN | B236: ADJ | C236: 1099. | D236: ="CVDf-"& mid(D235,6,3)+1 &"/1" -> CVDf-406/1 | E236: ="redni broj od kardinalnog broja " & substitute(C236,".","") -> redni broj od kardinalnog broja 1099 | H236: Cvetana | I236: S | J236: =len(E236) -> 36 | K236: =D236&C236 -> CVDf-406/11099. | L236: =ifna(VLOOKUP(K236,'Лист1'!D:E,2,false))
A237: RN | B237: ADJ | C237: 11. | D237: ="CVDf-"& mid(D236,6,3)+1 &"/1" -> CVDf-407/1 | E237: ="redni broj od kardinalnog broja " & substitute(C237,".","") -> redni broj od kardinalnog broja 11 | H237: Cvetana | I237: S | J237: =len(E237) -> 34 | K237: =D237&C237 -> CVDf-407/111. | L237: =ifna(VLOOKUP(K237,'Лист1'!D:E,2,false))
A238: RN | B238: ADJ | C238: 1100. | D238: ="CVDf-"& mid(D237,6,3)+1 &"/1" -> CVDf-408/1 | E238: ="redni broj od kardinalnog broja " & substitute(C238,".","") -> redni broj od kardinalnog broja 1100 | H238: Cvetana | I238: S | J238: =len(E238) -> 36 | K238: =D238&C238 -> CVDf-408/11100. | L238: =ifna(VLOOKUP(K238,'Лист1'!D:E,2,false))
A239: RN | B239: ADJ | C239: 1107. | D239: ="CVDf-"& mid(D238,6,3)+1 &"/1" -> CVDf-409/1 | E239: ="redni broj od kardinalnog broja " & substitute(C239,".","") -> redni broj od kardinalnog broja 1107 | H239: Cvetana | I239: S | J239: =len(E239) -> 36 | K239: =D239&C239 -> CVDf-409/11107. | L239: =ifna(VLOOKUP(K239,'Лист1'!D:E,2,false))
A240: RN | B240: ADJ | C240: 1152. | D240: ="CVDf-"& mid(D239,6,3)+1 &"/1" -> CVDf-410/1 | E240: ="redni broj od kardinalnog broja " & substitute(C240,".","") -> redni broj od kardinalnog broja 1152 | H240: Cvetana | I240: S | J240: =len(E240) -> 36 | K240: =D240&C240 -> CVDf-410/11152. | L240: =ifna(VLOOKUP(K240,'Лист1'!D:E,2,false))
... A445: RN | B445: ADJ | C445: 312. | D445: ="CVDf-"& mid(D444,6,3)+1 &"/1" -> CVDf-615/1 | E445: ="redni broj od kardinalnog broja " & substitute(C445,".","") -> redni broj od kardinalnog broja 312 | H445: Cvetana | I445: S | J445: =len(E445) -> 35 | K445: =D445&C445 -> CVDf-615/1312. | L445: =ifna(VLOOKUP(K445,'Лист1'!D:E,2,false))
A446: A | B446: ADJ | C446: 32-bitni | D446: ="CVDf-"& mid(D445,6,3)+1 &"/1" -> CVDf-616/1 | E446: koji ima 32 bita | H446: Cvetana | I446: S | J446: =len(E446) -> 16 | K446: =D446&C446 -> CVDf-616/132-bitni | L446: =ifna(VLOOKUP(K446,'Лист1'!D:E,2,false))
A447: RN | B447: ADJ | C447: 362. | D447: ="CVDf-"& mid(D446,6,3)+1 &"/1" -> CVDf-617/1 | E447: ="redni broj od kardinalnog broja " & substitute(C447,".","") -> redni broj od kardinalnog broja 362 | H447: Cvetana | I447: S | J447: =len(E447) -> 35 | K447: =D447&C447 -> CVDf-617/1362. | L447: =ifna(VLOOKUP(K447,'Лист1'!D:E,2,false))
A448: A | B448: ADJ | C448: 36-godišnji | D448: ="CVDf-"& mid(D447,6,3)+1 &"/1" -> CVDf-618/1 | E448: koji ima 36 godina | H448: Cvetana | I448: S | J448: =len(E448) -> 18 | K448: =D448&C448 -> CVDf-618/136-godišnji | L448: =ifna(VLOOKUP(K448,'Лист1'!D:E,2,false))
A449: RN | B449: ADJ | C449: 4. | D449: ="CVDf-"& mid(D448,6,3)+1 &"/1" -> CVDf-619/1 | E449: ="redni broj od kardinalnog broja " & substitute(C449,".","") -> redni broj od kardinalnog broja 4 | H449: Cvetana | I449: S | J449: =len(E449) -> 33 | K449: =D449&C449 -> CVDf-619/14. | L449: =ifna(VLOOKUP(K449,'Лист1'!D:E,2,false))
A450: RN | B450: ADJ | C450: 430. | D450: ="CVDf-"& mid(D449,6,3)+1 &"/1" -> CVDf-620/1 | E450: ="redni broj od kardinalnog broja " & substitute(C450,".","") -> redni broj od kardinalnog broja 430 | H450: Cvetana | I450: S | J450: =len(E450) -> 35 | K450: =D450&C450 -> CVDf-620/1430. | L450: =ifna(VLOOKUP(K450,'Лист1'!D:E,2,false))
A451: RN | B451: ADJ | C451: 447. | D451: ="CVDf-"& mid(D450,6,3)+1 &"/1" -> CVDf-621/1 | E451: ="redni broj od kardinalnog broja " & substitute(C451,".","") -> redni broj od kardinalnog broja 447 | H451: Cvetana | I451: S | J451: =len(E451) -> 35 | K451: =D451&C451 -> CVDf-621/1447. | L451: =ifna(VLOOKUP(K451,'Лист1'!D:E,2,false))
A452: RN | B452: ADJ | C452: 460 | D452: ="CVDf-"& mid(D451,6,3)+1 &"/1" -> CVDf-622/1 | E452: ="redni broj od kardinalnog broja " & substitute(C452,".","") -> redni broj od kardinalnog broja 460 | H452: Cvetana | I452: S | J452: =len(E452) -> 35 | K452: =D452&C452 -> CVDf-622/1460 | L452: =ifna(VLOOKUP(K452,'Лист1'!D:E,2,false))
A453: N | B453: NOUN | C453: tirozin | D453: ="CVDf-"& mid(D450,6,3)+1 &"/1" -> CVDf-621/1 | E453: neesencijalna aminokiselina koju telo sintetizuje iz druge aminokiseline zvane fenilalanin | F453: tirozin ; 4-hidroksifenilalanin ; L-tirozin | H453: Cvetana | I453: S | J453: =len(E453) -> 90 | K453: =D453&C453 -> CVDf-621/1tirozin | L453: =ifna(VLOOKUP(K453,'Лист1'!D:E,2,false))
A454: N | B454: NOUN | C454: 4-hidroksifenilalanin | D454: ="CVDf-"& mid(D451,6,3)+1 &"/1" -> CVDf-622/1 | E454: neesencijalna aminokiselina koju telo sintetizuje iz druge aminokiseline zvane fenilalanin | F454: tirozin ; 4-hidroksifenilalanin ; L-tirozin | H454: Cvetana | I454: S | J454: =len(E454) -> 90 | K454: =D454&C454 -> CVDf-622/14-hidroksifenilalanin | L454: =ifna(VLOOKUP(K454,'Лист1'!D:E,2,false))
A455: N | B455: NOUN | C455: L-tirozin | D455: ="CVDf-"& mid(D452,6,3)+1 &"/1" -> CVDf-623/1 | E455: neesencijalna aminokiselina koju telo sintetizuje iz druge aminokiseline zvane fenilalanin | F455: tirozin ; 4-hidroksifenilalanin ; L-tirozin | H455: Cvetana | I455: S | J455: =len(E455) -> 90 | K455: =D455&C455 -> CVDf-623/1L-tirozin | L455: =ifna(VLOOKUP(K455,'Лист1'!D:E,2,false))
A456: RN | B456: ADJ | C456: 5. | D456: ="CVDf-"& mid(D455,6,3)+1 &"/1" -> CVDf-624/1 | E456: ="redni broj od kardinalnog broja " & substitute(C456,".","") -> redni broj od kardinalnog broja 5 | H456: Cvetana | I456: S | J456: =len(E456) -> 33 | K456: =D456&C456 -> CVDf-624/15. | L456: =ifna(VLOOKUP(K456,'Лист1'!D:E,2,false))
A457: RN | B457: ADJ | C457: 572. | D457: ="CVDf-"& mid(D456,6,3)+1 &"/1" -> CVDf-625/1 | E457: ="redni broj od kardinalnog broja " & substitute(C457,".","") -> redni broj od kardinalnog broja 572 | H457: Cvetana | I457: S | J457: =len(E457) -> 35 | K457: =D457&C457 -> CVDf-625/1572. | L457: =ifna(VLOOKUP(K457,'Лист1'!D:E,2,false))
...

Sheet Лист2
A1: Sense_Entity_Lemma | B1: provera | C1: imaih | D1: Ima veliko slovo
A2: agencija | B2: =VLOOKUP(A2,Sheet1!C:H,6,false) -> SrpWN | C2: =countif(Sheet1!C:C,"="&A2) -> 2 | D2: =AND(CODE(LEFT(A2,1))>=65, CODE(LEFT(A2,1))<=90) -> FALSE
A3: akcija | B3: =VLOOKUP(A3,Sheet1!C:H,6,false) -> SrpWN | C3: =countif(Sheet1!C:C,"="&A3) -> 9 | D3: =AND(CODE(LEFT(A3,1))>=65, CODE(LEFT(A3,1))<=90) -> FALSE
A4: aktuelan | B4: =VLOOKUP(A4,Sheet1!C:H,6,false) -> SrpWN | C4: =countif(Sheet1!C:C,"="&A4) -> 1 | D4: =AND(CODE(LEFT(A4,1))>=65, CODE(LEFT(A4,1))<=90) -> FALSE
A5: akutan | B5: =VLOOKUP(A5,Sheet1!C:H,6,false) -> SrpWN | C5: =countif(Sheet1!C:C,"="&A5) -> 1 | D5: =AND(CODE(LEFT(A5,1))>=65, CODE(LEFT(A5,1))<=90) -> FALSE
A6: albanski | B6: =VLOOKUP(A6,Sheet1!C:H,6,false) -> SrpWN | C6: =countif(Sheet1!C:C,"="&A6) -> 1 | D6: =AND(CODE(LEFT(A6,1))>=65, CODE(LEFT(A6,1))<=90) -> FALSE
A7: album | B7: =VLOOKUP(A7,Sheet1!C:H,6,false) -> SrpWN | C7: =countif(Sheet1!C:C,"="&A7) -> 2 | D7: =AND(CODE(LEFT(A7,1))>=65, CODE(LEFT(A7,1))<=90) -> FALSE
A8: alkoholni | B8: =VLOOKUP(A8,Sheet1!C:H,6,false) -> SrpWN | C8: =countif(Sheet1!C:C,"="&A8) -> 1 | D8: =AND(CODE(LEFT(A8,1))>=65, CODE(LEFT(A8,1))<=90) -> FALSE
A9: alternativa | B9: =VLOOKUP(A9,Sheet1!C:H,6,false) -> SrpWN | C9: =countif(Sheet1!C:C,"="&A9) -> 1 | D9: =AND(CODE(LEFT(A9,1))>=65, CODE(LEFT(A9,1))<=90) -> FALSE
A10: amandman | B10: =VLOOKUP(A10,Sheet1!C:H,6,false) -> SrpWN | C10: =countif(Sheet1!C:C,"="&A10) -> 1 | D10: =AND(CODE(LEFT(A10,1))>=65, CODE(LEFT(A10,1))<=90) -> FALSE
A11: analiza | B11: =VLOOKUP(A11,Sheet1!C:H,6,false) -> SrpWN | C11: =countif(Sheet1!C:C,"="&A11) -> 3 | D11: =AND(CODE(LEFT(A11,1))>=65, CODE(LEFT(A11,1))<=90) -> FALSE
A12: angažovati | B12: =VLOOKUP(A12,Sheet1!C:H,6,false) -> SrpWN | C12: =countif(Sheet1!C:C,"="&A12) -> 2 | D12: =AND(CODE(LEFT(A12,1))>=65, CODE(LEFT(A12,1))<=90) -> FALSE
A13: anime | B13: =VLOOKUP(A13,Sheet1!C:H,6,false) -> Cvetana | C13: =countif(Sheet1!C:C,"="&A13) -> 1 | D13: =AND(CODE(LEFT(A13,1))>=65, CODE(LEFT(A13,1))<=90) -> FALSE
... A608: životinja | B608: =VLOOKUP(A608,Sheet1!C:H,6,false) -> SrpWN | C608: =countif(Sheet1!C:C,"="&A608) -> 1 | D608: =AND(CODE(LEFT(A608,1))>=65, CODE(LEFT(A608,1))<=90) -> FALSE

Sheet Лист1
A1: UPOS | B1: lemma | C1: senseID | E1: Akcija | F1: literals | G1: definition | H1: Велико слово
A2: ADJ | B2: anoniman | C2: ENG30-00120574-a | D2: =C2&B2 -> ENG30-00120574-aanoniman | E2: dodati | F2: anonimni | G2: čije ile ili identitet nisu poznati | H2: =EXACT(B2, LOWER(B2)) -> TRUE
A3: ADJ | B3: bakaran | C3: ENG30-02707889-a | D3: =C3&B3 -> ENG30-02707889-abakaran | E3: dodati | F3: bakarni | G3: koji je napravljen od bakra ili sadrži bakar | H3: =EXACT(B3, UPPER(B3)) -> FALSE
A4: ADJ | B4: doživotan | C4: ENG30-01440159-a | D4: =C4&B4 -> ENG30-01440159-adoživotan | E4: dodati | F4: doživotni; doživotno; od kolevke do groba | G4: traje kroz život | H4: =EXACT(B4, UPPER(B4)) -> FALSE
A5: ADJ | B5: drevan | C5: ENG30-01644847-a | D5: =C5&B5 -> ENG30-01644847-adrevan | E5: dodati | F5: drevni | G5: onaj koji je veoma star | H5: =EXACT(B5, UPPER(B5)) -> FALSE
A6: ADJ | B6: dvodoman | C6: ENG30-02479361-a | D6: =C6&B6 -> ENG30-02479361-advodoman | E6: dodati | F6: dvodomni; dvokomorni | G6: sastoji se od dve komore | H6: =EXACT(B6, UPPER(B6)) -> FALSE
A7: ADJ | B7: glotalan | C7: ENG30-02880924-a | D7: =C7&B7 -> ENG30-02880924-aglotalan | E7: dodati | F7: glotalni | G7: ili koji se odnosi na ili proizvodi glotis | H7: =EXACT(B7, UPPER(B7)) -> FALSE
A8: ADJ | B8: hibridan | C8: ENG30-01904485-a | D8: =C8&B8 -> ENG30-01904485-ahibridan | E8: dodati | F8: hibridni | G8: koji je nastao ukrštanjem sorti ili vrsta (biljaka ili životinja) | H8: =EXACT(B8, UPPER(B8)) -> FALSE
A9: ADJ | B9: kognitivan | C9: ENG30-02898584-a | D9: =C9&B9 -> ENG30-02898584-akognitivan | E9: dodati | F9: saznajni; kognitivni | G9: Koji je, odnosi se ili uključuje saznanje. | H9: =EXACT(B9, UPPER(B9)) -> FALSE
A10: ADJ | B10: ljubavan | C10: ENG30-01465214-a | D10: =C10&B10 -> ENG30-01465214-aljubavan | E10: dodati | F10: ljubavni; ljubavnički; romantičan | G10: koji izražava ili pobuđuje seksualnu ljubav ili romansu | H10: =EXACT(B10, UPPER(B10)) -> FALSE
A11: ADJ | B11: mentalan | C11: ENG30-01273910-a | D11: =C11&B11 -> ENG30-01273910-amentalan | E11: dodati | F11: duševni; mentalni; subjektivan | G11: mentalni čin koji se u potpunosti odvija u domenu uma | H11: =EXACT(B11, UPPER(B11)) -> FALSE
A12: ADJ | B12: mentalan | C12: ENG30-01779986-a | D12: =C12&B12 -> ENG30-01779986-amentalan | E12: dodati | F12: mentalni; umni | G12: koji uključuje um i intelektualne procese | H12: =EXACT(B12, UPPER(B12)) -> FALSE
A13: ADJ | B13: metalan | C13: ENG30-01527420-a | D13: =C13&B13 -> ENG30-01527420-ametalan | E13: dodati | F13: metal; metalik; metalni | G13: sadrži ili je napravljen od ili liči na metal | H13: =EXACT(B13, UPPER(B13)) -> FALSE
A14: ADJ | B14: monumentalan | C14: ENG30-02163468-a | D14: =C14&B14 -> ENG30-02163468-amonumentalan | E14: dodati | F14: monumentalni; monumentalno | G14: od izuzetnog značaja | H14: =EXACT(B14, UPPER(B14)) -> FALSE
... A122: VERB | B122: nalaziti | C122: ENG30-02731390-v | D122: =C122&B122 -> ENG30-02731390-vnalaziti | E122: briši | F122: naći se; nalaziti se; počivati | G122: zavisiti od nečeg drugog (izrečeno metaforom boravka na određenom mestu) | H122: =EXACT(B122, UPPER(B122)) -> FALSE
